Workbook

Sheet MIRORING MICRODEMAND
J1: =subtotal(9,J4:J3194) -> 5932 | K1: =subtotal(9,K4:K3194) -> 47592 | L1: =subtotal(9,L4:L3194) -> 893926583 | R1: KOMITMEN | AI1: GOLIVE
A2: =IFERROR(__xludf.DUMMYFUNCTION("QUERY(IMPORTRANGE(""https://docs.google.com/spreadsheets/d/1tvmbsYYalrgna1O0Aq5q2OEY3XxIv65LL8X1H4RN6tQ/edit"",""microdemand 2026!A1:Af""))"),"") | B2: =IFERROR(__xludf.DUMMYFUNCTION("""COMPUTED_VALUE"""),2736.0) -> 2736 | K2: =IFERROR(__xludf.DUMMYFUNCTION("""COMPUTED_VALUE"""),170760.0) -> 170760 | M2: =IFERROR(__xludf.DUMMYFUNCTION("""COMPUTED_VALUE"""),1.99627831031E11) -> 199627831031 | O2: =IFERROR(__xludf.DUMMYFUNCTION("""COMPUTED_VALUE"""),"RUMUS, HANYA UPDATE KOLOM P") -> RUMUS, HANYA UPDATE KOLOM P | P2: =IFERROR(__xludf.DUMMYFUNCTION("""COMPUTED_VALUE"""),"SUB STATUS JGN DICOPY PASTE !!!!! Perhatikan Ujung Nomor Sub status, menggambarkan status TSB") -> SUB STATUS JGN DICOPY PASTE !!!!! Perhatikan Ujung Nomor Sub status, menggambarkan status TSB | Q2: =IFERROR(__xludf.DUMMYFUNCTION("""COMPUTED_VALUE""")," ") | AC2: =IFERROR(__xludf.DUMMYFUNCTION("""COMPUTED_VALUE"""),"UPDATE OLEH SDI !!!") -> UPDATE OLEH SDI !!! | BS2: UPDATE KPI ED SUMBAGTENG MtD based on target HO | CD2: UPDATE KPI ED SUMBAGTENG YtD based on target HO
C3: =IFERROR(__xludf.DUMMYFUNCTION("""COMPUTED_VALUE"""),"NAMA LOP") -> NAMA LOP | D3: =IFERROR(__xludf.DUMMYFUNCTION("""COMPUTED_VALUE"""),"REGIONAL") -> REGIONAL | E3: =IFERROR(__xludf.DUMMYFUNCTION("""COMPUTED_VALUE"""),"AREA") -> AREA | F3: =IFERROR(__xludf.DUMMYFUNCTION("""COMPUTED_VALUE"""),"STO") -> STO | G3: =IFERROR(__xludf.DUMMYFUNCTION("""COMPUTED_VALUE"""),"REGION FMC") -> REGION FMC | H3: =IFERROR(__xludf.DUMMYFUNCTION("""COMPUTED_VALUE"""),"BRANCH FMC") -> BRANCH FMC | I3: =IFERROR(__xludf.DUMMYFUNCTION("""COMPUTED_VALUE"""),"BATCH PROGRAM") -> BATCH PROGRAM | N3: =IFERROR(__xludf.DUMMYFUNCTION("""COMPUTED_VALUE"""),"Mitra") -> Mitra | O3: =IFERROR(__xludf.DUMMYFUNCTION("""COMPUTED_VALUE"""),"Status") -> Status | P3: =IFERROR(__xludf.DUMMYFUNCTION("""COMPUTED_VALUE"""),"SUB STATUS KONS") -> SUB STATUS KONS | Q3: =IFERROR(__xludf.DUMMYFUNCTION("""COMPUTED_VALUE"""),"DETAIL STATUS") -> DETAIL STATUS | S3: =IFERROR(__xludf.DUMMYFUNCTION("""COMPUTED_VALUE"""),"TARGET GOLIVE APRIL") -> TARGET GOLIVE APRIL | T3: =IFERROR(__xludf.DUMMYFUNCTION("""COMPUTED_VALUE"""),"Prioritas 1 by Tsel") -> Prioritas 1 by Tsel | U3: =IFERROR(__xludf.DUMMYFUNCTION("""COMPUTED_VALUE"""),"PID (PROACTIVE)") -> PID (PROACTIVE) | V3: =IFERROR(__xludf.DUMMYFUNCTION("""COMPUTED_VALUE"""),"WASPANG") -> WASPANG | W3: =IFERROR(__xludf.DUMMYFUNCTION("""COMPUTED_VALUE"""),"PROJECT ADMIN") -> PROJECT ADMIN | X3: =IFERROR(__xludf.DUMMYFUNCTION("""COMPUTED_VALUE"""),"STATUS GOLIVE") -> STATUS GOLIVE | Y3: =IFERROR(__xludf.DUMMYFUNCTION("""COMPUTED_VALUE"""),"KENDALA GOLIVE") -> KENDALA GOLIVE | Z3: =IFERROR(__xludf.DUMMYFUNCTION("""COMPUTED_VALUE"""),"Progres MINOL") -> Progres MINOL | AC3: =IFERROR(__xludf.DUMMYFUNCTION("""COMPUTED_VALUE"""),"ID SW ABD") -> ID SW ABD | AF3: =IFERROR(__xludf.DUMMYFUNCTION("""COMPUTED_VALUE"""),"KET") -> KET | AH3: KOMITMEN TA | AI3: DEVIASI DARI KOMITMEN | AJ3: KET DEV | AK3: PLAN APRIL | AX3: GRAND TOTAL ODP & PORT | BB3: =subtotal(9,BB7:BB3194) -> 8 | BC3: =subtotal(9,BC7:BC3194) -> 64 | BS3: =UPPER(TEXT(#REF!,"[$-421]DDDD, DD MMMM YYYY")) -> #REF! | CD3: =UPPER(TEXT(#REF!,"[$-421]DDDD, DD MMMM YYYY")) -> #REF!
A4: =IFERROR(__xludf.DUMMYFUNCTION("""COMPUTED_VALUE"""),2026.0) -> 2026 | B4: =IFERROR(__xludf.DUMMYFUNCTION("""COMPUTED_VALUE"""),1.0882441E7) -> 10882441 | C4: =IFERROR(__xludf.DUMMYFUNCTION("""COMPUTED_VALUE"""),"SMU-ODC-PMS-FBS D10 BANTAN RESIDEN") -> SMU-ODC-PMS-FBS D10 BANTAN RESIDEN | D4: =IFERROR(__xludf.DUMMYFUNCTION("""COMPUTED_VALUE"""),"REGIONAL I") -> REGIONAL I | E4: =IFERROR(__xludf.DUMMYFUNCTION("""COMPUTED_VALUE"""),"SUMUT") -> SUMUT | F4: =IFERROR(__xludf.DUMMYFUNCTION("""COMPUTED_VALUE"""),"PMS") -> PMS | G4: =IFERROR(__xludf.DUMMYFUNCTION("""COMPUTED_VALUE"""),"SUMBAGUT") -> SUMBAGUT | H4: =IFERROR(__xludf.DUMMYFUNCTION("""COMPUTED_VALUE"""),"PEMATANG SIANTAR") -> PEMATANG SIANTAR | I4: =IFERROR(__xludf.DUMMYFUNCTION("""COMPUTED_VALUE"""),"Batch 1") -> Batch 1 | J4: =IFERROR(__xludf.DUMMYFUNCTION("""COMPUTED_VALUE"""),13.0) -> 13 | K4: =IFERROR(__xludf.DUMMYFUNCTION("""COMPUTED_VALUE"""),104.0) -> 104 | L4: =IFERROR(__xludf.DUMMYFUNCTION("""COMPUTED_VALUE"""),1282323.0) -> 1282323 | M4: =IFERROR(__xludf.DUMMYFUNCTION("""COMPUTED_VALUE"""),1.33361508E8) -> 133361508 | N4: =IFERROR(__xludf.DUMMYFUNCTION("""COMPUTED_VALUE"""),"PT GARINDO TECHNO MANDIRI") -> PT GARINDO TECHNO MANDIRI | O4: =IFERROR(__xludf.DUMMYFUNCTION("""COMPUTED_VALUE"""),"5. INSTALASI") -> 5. INSTALASI | P4: =IFERROR(__xludf.DUMMYFUNCTION("""COMPUTED_VALUE"""),"5.4 Proses Penanaman Tiang") -> 5.4 Proses Penanaman Tiang | Q4: =IFERROR(__xludf.DUMMYFUNCTION("""COMPUTED_VALUE"""),"27/4 hari ini team proses tanam tiang total 21 batang, KU 24 (3643 ) belum progres, KU 12c 481 belum progres ODP 13 belum progres, , 23/4 prepair tim untuk pengambilan material, 22/4 proses input alista kendala penambahan PA, 21/4 proses input alista k"&"endala ganti pid baru, 20/4 proses input alista kendala masih penambahan PA, 16/4 proses input alista kendala masih penambahan PA, 15/4 proses input alista kendala masih penambahan PA, 14/4 proses input alista kendala masih penambahan PA, 13/4 proses inpu"&"t material di alista, 10/4 cpp naik 1,3, 9/4 menunggu boq kml hasil survey, 8/4 mitra belum kelokasi untk survey, 6/4 plan survey besok 7 april, 5/4 tim belum turun ke lokasi untuk survey, 1/4 plan survey bsk tgl 2 april (kendala hujan di lokasi), 31/3 pl"&"an survey tgl 1 april, 30/3 plan survey tgl 31 maret, 27/3 plan survey tanggal 30, 26/3 prepair team untuk survey kelokasi, 22/3 prepair team untuk survey kelokasi, 18/3 plan survey seletal lebaran, 16/3 plan survey besok 17 maret, 2/3 prepairt team untu"&"k survey kelokasi ( peralihan dari mitra cpm), 27/2 prepair team untuk survey kelokasi, 25/2 menunggu boq kml dari sdi, 24/2 plan survey ulang redesign , drop dikarnakan diloaksi masih banyak odp yg kosong, (07/01) Persiapan ") -> 27/4 hari ini team proses tanam tiang total 21 batang, KU 24 (3643 ) belum progres, KU 12c 481 belum progres ODP 13 belum progres, , 23/4 prepair tim untuk pengambilan material, 22/4 proses input alista kendala penambahan PA, 21/4 proses input alista kendala ganti pid baru, 20/4 proses input alista kendala masih penambahan PA, 16/4 proses input alista kendala masih penambahan PA, 15/4 proses input alista kendala masih penambahan PA, 14/4 proses input alista kendala masih penambahan PA, 13/4 proses input material di alista, 10/4 cpp naik 1,3, 9/4 menunggu boq kml hasil survey, 8/4 mitra belum kelokasi untk survey, 6/4 plan survey besok 7 april, 5/4 tim belum turun ke lokasi untuk survey, 1/4 plan survey bsk tgl 2 april (kendala hujan di lokasi), 31/3 plan survey tgl 1 april, 30/3 plan survey tgl 31 maret, 27/3 plan survey tanggal 30, 26/3 prepair team untuk survey kelokasi, 22/3 prepair team untuk survey kelokasi, 18/3 plan survey seletal lebaran, 16/3 plan survey besok 17 maret, 2/3 prepairt team untuk survey kelokasi ( peralihan dari mitra cpm), 27/2 prepair team untuk survey kelokasi, 25/2 menunggu boq kml dari sdi, 24/2 plan survey ulang redesign , drop dikarnakan diloaksi masih banyak odp yg kosong, (07/01) Persiapan | U4: =IFERROR(__xludf.DUMMYFUNCTION("""COMPUTED_VALUE"""),"W03-2193/2024") -> W03-2193/2024 | X4: =IFERROR(__xludf.DUMMYFUNCTION("""COMPUTED_VALUE"""),"BELUM GOLIVE") -> BELUM GOLIVE | Z4: =IFERROR(__xludf.DUMMYFUNCTION("""COMPUTED_VALUE"""),"#N/A") -> #N/A | AF4: =IFERROR(__xludf.DUMMYFUNCTION("""COMPUTED_VALUE"""),"Draft BA DROP") -> Draft BA DROP | AI4: =IF(OR(AH4="",AE4=""),"",AH4-AE4) | AJ4: =if(AI4>=0,"not yet","lewat komitmen") -> not yet | AX4: REAL GOLIVE ODP & PORT HI | BB4: 74 | BC4: 592 | BS4: =NOW() -> 46140.378
A5: =IFERROR(__xludf.DUMMYFUNCTION("""COMPUTED_VALUE"""),2026.0) -> 2026 | B5: =IFERROR(__xludf.DUMMYFUNCTION("""COMPUTED_VALUE"""),1.0991375E7) -> 10991375 | C5: =IFERROR(__xludf.DUMMYFUNCTION("""COMPUTED_VALUE"""),"MDN PT3 P7I2 LBP-FK PERUM MULIA RESIDENCE 8") -> MDN PT3 P7I2 LBP-FK PERUM MULIA RESIDENCE 8 | D5: =IFERROR(__xludf.DUMMYFUNCTION("""COMPUTED_VALUE"""),"REGIONAL I") -> REGIONAL I | E5: =IFERROR(__xludf.DUMMYFUNCTION("""COMPUTED_VALUE"""),"MEDAN") -> MEDAN | F5: =IFERROR(__xludf.DUMMYFUNCTION("""COMPUTED_VALUE"""),"LBP") -> LBP | G5: =IFERROR(__xludf.DUMMYFUNCTION("""COMPUTED_VALUE"""),"SUMBAGUT") -> SUMBAGUT | H5: =IFERROR(__xludf.DUMMYFUNCTION("""COMPUTED_VALUE"""),"MEDAN") -> MEDAN | I5: =IFERROR(__xludf.DUMMYFUNCTION("""COMPUTED_VALUE"""),"Batch 1") -> Batch 1 | J5: =IFERROR(__xludf.DUMMYFUNCTION("""COMPUTED_VALUE"""),2.0) -> 2 | K5: =IFERROR(__xludf.DUMMYFUNCTION("""COMPUTED_VALUE"""),16.0) -> 16 | L5: =IFERROR(__xludf.DUMMYFUNCTION("""COMPUTED_VALUE"""),861263.0) -> 861263 | M5: =IFERROR(__xludf.DUMMYFUNCTION("""COMPUTED_VALUE"""),1.3780207E7) -> 13780207 | N5: =IFERROR(__xludf.DUMMYFUNCTION("""COMPUTED_VALUE"""),"PT TEKNOLOGI KARYA MANDIRI") -> PT TEKNOLOGI KARYA MANDIRI | O5: =IFERROR(__xludf.DUMMYFUNCTION("""COMPUTED_VALUE"""),"0. DROP") -> 0. DROP | P5: =IFERROR(__xludf.DUMMYFUNCTION("""COMPUTED_VALUE"""),"0.2 Tidak Dapat Izin Warga/Kades/Lurah/Developer") -> 0.2 Tidak Dapat Izin Warga/Kades/Lurah/Developer | Q5: =IFERROR(__xludf.DUMMYFUNCTION("""COMPUTED_VALUE"""),"20/04 tidak dapat ijin developer 09/04 fu perizinan ke CHAM 02/03 proses izin devloper (07/01) Persiapan") -> 20/04 tidak dapat ijin developer 09/04 fu perizinan ke CHAM 02/03 proses izin devloper (07/01) Persiapan | V5: =IFERROR(__xludf.DUMMYFUNCTION("""COMPUTED_VALUE"""),"27/Apr/2026") -> 27/Apr/2026 | X5: =IFERROR(__xludf.DUMMYFUNCTION("""COMPUTED_VALUE"""),"BELUM GOLIVE") -> BELUM GOLIVE | Z5: =IFERROR(__xludf.DUMMYFUNCTION("""COMPUTED_VALUE"""),"#N/A") -> #N/A | AI5: =IF(OR(R5="",AE5=""),"",R5-AE5) | AJ5: =if(AI5>=0,"not yet","lewat komitmen") -> not yet | AX5: ACH | BB5: =BB4/BB3 -> 9.25 | BC5: =BC4/BC3 -> 9.25 | BS5: DISTRICT | BT5: PT2 | BW5: PT3 | BZ5: DEPLOYMENT ALPRO | CD5: DISTRICT | CE5: PT2 | CH5: PT3 | CK5: DEPLOYMENT ALPRO
A6: =IFERROR(__xludf.DUMMYFUNCTION("""COMPUTED_VALUE"""),2026.0) -> 2026 | B6: =IFERROR(__xludf.DUMMYFUNCTION("""COMPUTED_VALUE"""),1.0991468E7) -> 10991468 | C6: =IFERROR(__xludf.DUMMYFUNCTION("""COMPUTED_VALUE"""),"MDN PT3 P7I2 TJR-FXX UKNOWN RESIDENCE") -> MDN PT3 P7I2 TJR-FXX UKNOWN RESIDENCE | D6: =IFERROR(__xludf.DUMMYFUNCTION("""COMPUTED_VALUE"""),"REGIONAL I") -> REGIONAL I | E6: =IFERROR(__xludf.DUMMYFUNCTION("""COMPUTED_VALUE"""),"MEDAN") -> MEDAN | F6: =IFERROR(__xludf.DUMMYFUNCTION("""COMPUTED_VALUE"""),"TJR") -> TJR | G6: =IFERROR(__xludf.DUMMYFUNCTION("""COMPUTED_VALUE"""),"SUMBAGUT") -> SUMBAGUT | H6: =IFERROR(__xludf.DUMMYFUNCTION("""COMPUTED_VALUE"""),"MEDAN") -> MEDAN | I6: =IFERROR(__xludf.DUMMYFUNCTION("""COMPUTED_VALUE"""),"Batch 1") -> Batch 1 | J6: =IFERROR(__xludf.DUMMYFUNCTION("""COMPUTED_VALUE"""),9.0) -> 9 | K6: =IFERROR(__xludf.DUMMYFUNCTION("""COMPUTED_VALUE"""),72.0) -> 72 | L6: =IFERROR(__xludf.DUMMYFUNCTION("""COMPUTED_VALUE"""),1369463.0) -> 1369463 | M6: =IFERROR(__xludf.DUMMYFUNCTION("""COMPUTED_VALUE"""),9.8601293E7) -> 98601293 | N6: =IFERROR(__xludf.DUMMYFUNCTION("""COMPUTED_VALUE"""),"PT SINAR KEPRI SEJAHTERA") -> PT SINAR KEPRI SEJAHTERA | O6: =IFERROR(__xludf.DUMMYFUNCTION("""COMPUTED_VALUE"""),"0. DROP") -> 0. DROP | P6: =IFERROR(__xludf.DUMMYFUNCTION("""COMPUTED_VALUE"""),"0.1 Double Order") -> 0.1 Double Order | Q6: =IFERROR(__xludf.DUMMYFUNCTION("""COMPUTED_VALUE"""),"17/02 double order IHLD 11081234") -> 17/02 double order IHLD 11081234 | X6: =IFERROR(__xludf.DUMMYFUNCTION("""COMPUTED_VALUE"""),"BELUM GOLIVE") -> BELUM GOLIVE | Z6: =IFERROR(__xludf.DUMMYFUNCTION("""COMPUTED_VALUE"""),"#N/A") -> #N/A | AF6: =IFERROR(__xludf.DUMMYFUNCTION("""COMPUTED_VALUE"""),"Draft BA DROP") -> Draft BA DROP | AI6: =IF(OR(R6="",AE6=""),"",R6-AE6) | AJ6: =if(AI6>=0,"not yet","lewat komitmen") -> not yet | AR6: NO | AS6: TAHUN | AT6: ID-IHLD | AU6: NAMA LOP | AV6: REGIONAL | AW6: AREA | AX6: STO | AY6: REGION FMC | AZ6: BRANCH FMC | BA6: BATCH PROGRAM | BB6: ODP PLAN | BC6: PORT PLAN | BD6: NAMA MITRA | BE6: STATUS | BF6: SUB STATUS KONS | BG6: DETAIL STATUS | BH6: BULAN GOLIVE | BI6: KOMITMEN GOLIVE | BJ6: Tgl Golive | BK6: FINAL | BL6: POTENSI PORT GL HARIAN | BT6: Target | BU6: Realisasi MtD | BV6: Ach | BW6: Target | BX6: Realisasi MtD | BY6: Ach | BZ6: Target | CA6: Realisasi MtD | CB6: Ach | CE6: Target | CF6: Realisasi YtD | CG6: Ach | CH6: Target | CI6: Realisasi YtD | CJ6: Ach | CK6: Target | CL6: Realisasi YtD | CM6: Ach
A7: =IFERROR(__xludf.DUMMYFUNCTION("""COMPUTED_VALUE"""),2026.0) -> 2026 | B7: =IFERROR(__xludf.DUMMYFUNCTION("""COMPUTED_VALUE"""),1.1091798E7) -> 11091798 | C7: =IFERROR(__xludf.DUMMYFUNCTION("""COMPUTED_VALUE"""),"SMU ODC-SIH-FAJ D02 CLUST SUMATERA UTARA_1414") -> SMU ODC-SIH-FAJ D02 CLUST SUMATERA UTARA_1414 | D7: =IFERROR(__xludf.DUMMYFUNCTION("""COMPUTED_VALUE"""),"REGIONAL I") -> REGIONAL I | E7: =IFERROR(__xludf.DUMMYFUNCTION("""COMPUTED_VALUE"""),"SUMUT") -> SUMUT | F7: =IFERROR(__xludf.DUMMYFUNCTION("""COMPUTED_VALUE"""),"SIH") -> SIH | G7: =IFERROR(__xludf.DUMMYFUNCTION("""COMPUTED_VALUE"""),"SUMBAGUT") -> SUMBAGUT | H7: =IFERROR(__xludf.DUMMYFUNCTION("""COMPUTED_VALUE"""),"RANTAU PRAPAT") -> RANTAU PRAPAT | I7: =IFERROR(__xludf.DUMMYFUNCTION("""COMPUTED_VALUE"""),"Batch 1") -> Batch 1 | J7: =IFERROR(__xludf.DUMMYFUNCTION("""COMPUTED_VALUE"""),20.0) -> 20 | K7: =IFERROR(__xludf.DUMMYFUNCTION("""COMPUTED_VALUE"""),160.0) -> 160 | L7: =IFERROR(__xludf.DUMMYFUNCTION("""COMPUTED_VALUE"""),640620.0) -> 640620 | M7: =IFERROR(__xludf.DUMMYFUNCTION("""COMPUTED_VALUE"""),1.02499169E8) -> 102499169 | N7: =IFERROR(__xludf.DUMMYFUNCTION("""COMPUTED_VALUE"""),"PT SALTTEK DUMPANG JAYA") -> PT SALTTEK DUMPANG JAYA | O7: =IFERROR(__xludf.DUMMYFUNCTION("""COMPUTED_VALUE"""),"3. PERIZINAN") -> 3. PERIZINAN | P7: =IFERROR(__xludf.DUMMYFUNCTION("""COMPUTED_VALUE"""),"3.1 Submit permohon ke PU") -> 3.1 Submit permohon ke PU | Q7: =IFERROR(__xludf.DUMMYFUNCTION("""COMPUTED_VALUE"""),"27/4 ( ada nya kenaikan nilai dan cpp karna plan pembangunan hanya d2 tetapi dilokasi belum ada pembangunan odc dan new d1, ) paralel menunggu ttd GM terkait pengantar ijin pu prov (ada permintaan biaya dari pu sebesar 45jt), 24/4 ( ada nya kenaikan "&"nilai dan cpp karna plan pembangunan hanya d2 tetapi dilokasi belum ada pembangunan odc dan new d1, ) paralel menunggu ttd GM terkait pengantar ijin pu prov (ada permintaan biaya dari pu sebesar 45jt), 23/4 ( ada nya kenaikan nilai dan cpp karna pla"&"n pembangunan hanya d2 tetapi dilokasi belum ada pembangunan odc dan new d1, ) paralel menunggu ttd GM terkait pengantar ijin pu prov (ada permintaan biaya dari pu sebesar 45jt), 22/4 menunggu ttd GM terkait pengantar ijin pu prov (ada permintaan biay"&"a dari pu sebesar 45jt), 21/4 menunggu ttd GM terkait pengantar ijin pu prov (45jt), 20/4 menunggu ttd GM terkait pengantar ijin pu prov (45jt), 16/4 menunggu ttd GM terkait pengantar ijin pu prov (45jt), 15/4 menunggu approve pengantar ijin pu prov (45jt"&") paralel req matrial, 14/4 menunggu approve pengantar ijin pu prov (45jt) paralel req matrial, 13/4 menunggu approve pengantar ijin pu prov (45jt) paralel req matrial, 9/4 menunggu approve pengantar ijin pu prov (45jt) paralel req matrial, 8/4 menu"&"nggu approve pengantar ijin pu prov (45jt) paralel req matrial, 6/4 menunggu approve pengantar ijin pu prov (45jt) paralel req matrial, 5/4 menunggu approve pengantar ijin pu prov (45jt) paralel req matrial, 1/4 menunggu approve pengantar ijin pu pr"&"ov (45jt) paralel req matrial, 31/3 menunggu approve pengantar ijin pu prov (45jt) paralel req matrial, 30/3 menunggu approve pengantar ijin pu prov (45jt) paralel req matrial, 27/3 menunggu approve pengantar ijin pu prov (45jt) paralel req matrial, 2"&"6/3 menunggu approve pengantar ijin pu prov (45jt) paralel req matrial, 22/3 menunggu approve pengantar ijin pu prov (45jt) paralel req matrial, 18/3 menunggu approve pengantar ijin pu prov (45jt) paralel req matrial, 16/3 menunggu pengantar ijin pu p"&"rov (45jt) paralel req matrial, 13/3 menunggu pengantar ijin pu prov (45jt) paralel req matrial, 11/3 menunggu pengantar ijin pu prov (45jt) paralel req matrial, 10/3 menunggu pengantar ijin pu prov (45jt) paralel req matrial, 6/3 menunggu pengantar i"&"jin pu prov (45jt) paralel req matrial, 5/3 menunggu pengantar ijin pu prov (45jt) paralel req matrial, 4/3 menunggu pengantar ijin pu prov (45jt) paralel req matrial, 3/3 menunggu pengantar ijin pu prov (45jt) paralel req matrial, 2/3 menunggu pengan"&"tar ijin pu prov (45jt) paralel req matrial, 25/2 menunggu pengantar ijin pu prov (45jt) paralel req matrial, 24/2 menunggu pengantar ijin pu prov (45jt) paralel req matrial, 23/2 menunggu pengantar ijin pu prov (45jt) paralel req matrial, 20/2 menun"&"ggu pengantar ijin pu prov (45jt) paralel req matrial,19/2 menunggu pengantar ijin pu prov (45jt) paralel req matrial, 16/2 menunggu pengantar ijin pu prov (45jt) paralel req matrial, 13/2 menunggu pengantar ijin pu prov (45jt) paralel req matrial, 11"&"/2 menunggu pengantar ijin pu prov (45jt) paralel req matrial, 10/2 menunggu pengantar ijin pu prov (45jt) paralel req matrial, 9/2 menunggu pengantar ijin pu prov (45jt) paralel req matrial, 6/2 menunggu pengantar ijin pu prov paralel req matrial, 5"&"/2 menunggu pengantar ijin pu prov paralel req matrial, 3/2 menunggu pengantar ijin pu prov paralel req matrial, 2/2 menunggu pengantar ijin pu prov paralel req matrial, 1/2 menunggu pengantar ijin pu prov paralel req matrial, 30/1 menunggu pengantar iji"&"n pu prov paralel req matrial, 28/1 menunggu pengantar ijin pu prov paralel req matrial, 27/1 proses req pengantar ijin pu prov paralel req matrial, 26/1 proses req pengantar iin pu prov paralel req matrial, 23/1 prepair team untuk survey ulang hasil rede"&"sign, 22/1 dilokasi belum ada pembangunan odc dan distribusi 1, 21/1 dilokasi belum ada pembangunan odc dan distribusi 1, 20/1 menunggu info dari req terkait odc dan dis 1 belum ada dibanguan dilapangan, 19/1 plan survey 20/1, 15/1 plan survey 20/1, 14"&"/1 plan survey 22/1, 13/1 prepair team untuk penjadwalan survey, (07/01) Persiapan") -> 27/4 ( ada nya kenaikan nilai dan cpp karna plan pembangunan hanya d2 tetapi dilokasi belum ada pembangunan odc dan new d1, ) paralel menunggu ttd GM terkait pengantar ijin pu prov (ada permintaan biaya dari pu sebesar 45jt), 24/4 ( ada nya kenaikan nilai dan cpp karna plan pembangunan hanya d2 tetapi dilokasi belum ada pembangunan odc dan new d1, ) paralel menunggu ttd GM terkait pengantar ijin pu prov (ada permintaan biaya dari pu sebesar 45jt), 23/4 ( ada nya kenaikan nilai dan cpp karna plan pembangunan hanya d2 tetapi dilokasi belum ada pembangunan odc dan new d1, ) paralel menunggu ttd GM terkait pengantar ijin pu prov (ada permintaan biaya dari pu sebesar 45jt), 22/4 menunggu ttd GM terkait pengantar ijin pu prov (ada permintaan biaya dari pu sebesar 45jt), 21/4 menunggu ttd GM terkait pengantar ijin pu prov (45jt), 20/4 menunggu ttd GM terkait pengantar ijin pu prov (45jt), 16/4 menunggu ttd GM terkait pengantar ijin pu prov (45jt), 15/4 menunggu approve pengantar ijin pu prov (45jt) paralel req matrial, 14/4 menunggu approve pengantar ijin pu prov (45jt) paralel req matrial, 13/4 menunggu approve pengantar ijin pu prov (45jt) paralel req matrial, 9/4 menunggu approve pengantar ijin pu prov (45jt) paralel req matrial, 8/4 menunggu approve pengantar ijin pu prov (45jt) paralel req matrial, 6/4 menunggu approve pengantar ijin pu prov (45jt) paralel req matrial, 5/4 menunggu approve pengantar ijin pu prov (45jt) paralel req matrial, 1/4 menunggu approve pengantar ijin pu prov (45jt) paralel req matrial, 31/3 menunggu approve pengantar ijin pu prov (45jt) paralel req matrial, 30/3 menunggu approve pengantar ijin pu prov (45jt) paralel req matrial, 27/3 menunggu approve pengantar ijin pu prov (45jt) paralel req matrial, 26/3 menunggu approve pengantar ijin pu prov (45jt) paralel req matrial, 22/3 menunggu approve pengantar ijin pu prov (45jt) paralel req matrial, 18/3 menunggu approve pengantar ijin pu prov (45jt) paralel req matrial, 16/3 menunggu pengantar ijin pu prov (45jt) paralel req matrial, 13/3 menunggu pengantar ijin pu prov (45jt) paralel req matrial, 11/3 menunggu pengantar ijin pu prov (45jt) paralel req matrial, 10/3 menunggu pengantar ijin pu prov (45jt) paralel req matrial, 6/3 menunggu pengantar ijin pu prov (45jt) paralel req matrial, 5/3 menunggu pengantar ijin pu prov (45jt) paralel req matrial, 4/3 menunggu pengantar ijin pu prov (45jt) paralel req matrial, 3/3 menunggu pengantar ijin pu prov (45jt) paralel req matrial, 2/3 menunggu pengantar ijin pu prov (45jt) paralel req matrial, 25/2 menunggu pengantar ijin pu prov (45jt) paralel req matrial, 24/2 menunggu pengantar ijin pu prov (45jt) paralel req matrial, 23/2 menunggu pengantar ijin pu prov (45jt) paralel req matrial, 20/2 menunggu pengantar ijin pu prov (45jt) paralel req matrial,19/2 menunggu pengantar ijin pu prov (45jt) paralel req matrial, 16/2 menunggu pengantar ijin pu prov (45jt) paralel req matrial, 13/2 menunggu pengantar ijin pu prov (45jt) paralel req matrial, 11/2 menunggu pengantar ijin pu prov (45jt) paralel req matrial, 10/2 menunggu pengantar ijin pu prov (45jt) paralel req matrial, 9/2 menunggu pengantar ijin pu prov (45jt) paralel req matrial, 6/2 menunggu pengantar ijin pu prov paralel req matrial, 5/2 menunggu pengantar ijin pu prov paralel req matrial, 3/2 menunggu pengantar ijin pu prov paralel req matrial, 2/2 menunggu pengantar ijin pu prov paralel req matrial, 1/2 menunggu pengantar ijin pu prov paralel req matrial, 30/1 menunggu pengantar ijin pu prov paralel req matrial, 28/1 menunggu pengantar ijin pu prov paralel req matrial, 27/1 proses req pengantar ijin pu prov paralel req matrial, 26/1 proses req pengantar iin pu prov paralel req matrial, 23/1 prepair team untuk survey ulang hasil redesign, 22/1 dilokasi belum ada pembangunan odc dan distribusi 1, 21/1 dilokasi belum ada pembangunan odc dan distribusi 1, 20/1 menunggu info dari req terkait odc dan dis 1 belum ada dibanguan dilapangan, 19/1 plan survey 20/1, 15/1 plan survey 20/1, 14/1 plan survey 22/1, 13/1 prepair team untuk penjadwalan survey, (07/01) Persiapan | U7: =IFERROR(__xludf.DUMMYFUNCTION("""COMPUTED_VALUE"""),"TIF-1398/2026") -> TIF-1398/2026 | X7: =IFERROR(__xludf.DUMMYFUNCTION("""COMPUTED_VALUE"""),"BELUM GOLIVE") -> BELUM GOLIVE | Y7: =IFERROR(__xludf.DUMMYFUNCTION("""COMPUTED_VALUE"""),"Izin pu") -> Izin pu | Z7: =IFERROR(__xludf.DUMMYFUNCTION("""COMPUTED_VALUE"""),"0. Drop Site") -> 0. Drop Site | AI7: =IF(OR(R7="",AE7=""),"",R7-AE7) | AJ7: =if(AI7>=0,"not yet","lewat komitmen") -> not yet | AR7: 1 | AS7: 2026 | AT7: 12678877 | AU7: SMB PT3-SWL-FB KOTA SAWAHLUNTO_93280 | AV7: REGIONAL I | AW7: =xlookup(AX7,BANTU!B:B,BANTU!A:A) -> PADANG | AX7: SWL | AY7: SUMBAGTENG | AZ7: PADANG | BA7: Batch 3 | BB7: 6 | BC7: 48 | BD7: PT TANJUNG PUTRA PRIMA | BE7: 6. FINISH INSTALASI | BF7: 6.8 Sudah Submit ABD ke SDI | BG7: (05/03) ABD done submit ke sdi (02/03) ABD OGP submit ke sdi (18/02) penarikan kabel PLAN FI 22/02 (29/01) proses delivery material (21/01) proses CReate PID (07/01) Persiapan | BH7: MARET | BI7: 46086 | BK7: GOLIVE | BL7: 72
A8: =IFERROR(__xludf.DUMMYFUNCTION("""COMPUTED_VALUE"""),2026.0) -> 2026 | B8: =IFERROR(__xludf.DUMMYFUNCTION("""COMPUTED_VALUE"""),1.0997432E7) -> 10997432 | C8: =IFERROR(__xludf.DUMMYFUNCTION("""COMPUTED_VALUE"""),"SMU-P7I2-ODC-PMS-FAP-D05 KOPERASI") -> SMU-P7I2-ODC-PMS-FAP-D05 KOPERASI | D8: =IFERROR(__xludf.DUMMYFUNCTION("""COMPUTED_VALUE"""),"REGIONAL I") -> REGIONAL I | E8: =IFERROR(__xludf.DUMMYFUNCTION("""COMPUTED_VALUE"""),"SUMUT") -> SUMUT | F8: =IFERROR(__xludf.DUMMYFUNCTION("""COMPUTED_VALUE"""),"PMS") -> PMS | G8: =IFERROR(__xludf.DUMMYFUNCTION("""COMPUTED_VALUE"""),"SUMBAGUT") -> SUMBAGUT | H8: =IFERROR(__xludf.DUMMYFUNCTION("""COMPUTED_VALUE"""),"PEMATANG SIANTAR") -> PEMATANG SIANTAR | I8: =IFERROR(__xludf.DUMMYFUNCTION("""COMPUTED_VALUE"""),"Batch 1") -> Batch 1 | J8: =IFERROR(__xludf.DUMMYFUNCTION("""COMPUTED_VALUE"""),4.0) -> 4 | K8: =IFERROR(__xludf.DUMMYFUNCTION("""COMPUTED_VALUE"""),32.0) -> 32 | L8: =IFERROR(__xludf.DUMMYFUNCTION("""COMPUTED_VALUE"""),1173150.0) -> 1173150 | M8: =IFERROR(__xludf.DUMMYFUNCTION("""COMPUTED_VALUE"""),3.7540791E7) -> 37540791 | N8: =IFERROR(__xludf.DUMMYFUNCTION("""COMPUTED_VALUE"""),"PT UPENTEL INTERNASIONAL") -> PT UPENTEL INTERNASIONAL | O8: =IFERROR(__xludf.DUMMYFUNCTION("""COMPUTED_VALUE"""),"0. DROP") -> 0. DROP | P8: =IFERROR(__xludf.DUMMYFUNCTION("""COMPUTED_VALUE"""),"0.2 Tidak Dapat Izin Warga/Kades/Lurah/Developer") -> 0.2 Tidak Dapat Izin Warga/Kades/Lurah/Developer | Q8: =IFERROR(__xludf.DUMMYFUNCTION("""COMPUTED_VALUE"""),"DROP tidak ada ijiin akses dari warga dan pemerintah setempat, 13/1 menunggu info kelanjutan dari mitra est besok 14/1, (07/01) Persiapan") -> DROP tidak ada ijiin akses dari warga dan pemerintah setempat, 13/1 menunggu info kelanjutan dari mitra est besok 14/1, (07/01) Persiapan | U8: =IFERROR(__xludf.DUMMYFUNCTION("""COMPUTED_VALUE"""),"W03-1975/2024") -> W03-1975/2024 | X8: =IFERROR(__xludf.DUMMYFUNCTION("""COMPUTED_VALUE"""),"BELUM GOLIVE") -> BELUM GOLIVE | Z8: =IFERROR(__xludf.DUMMYFUNCTION("""COMPUTED_VALUE"""),"#N/A") -> #N/A | AF8: =IFERROR(__xludf.DUMMYFUNCTION("""COMPUTED_VALUE"""),"Draft BA DROP") -> Draft BA DROP | AI8: =IF(OR(R8="",AE8=""),"",R8-AE8) | AJ8: =if(AI8>=0,"not yet","lewat komitmen") -> not yet | AR8: 2 | AS8: 2026 | AT8: 12822895 | AU8: RKP TSEL PT3 LBJ-FBF BKG NUSANTARA 1 | AV8: REGIONAL I | AW8: =xlookup(AX8,BANTU!B:B,BANTU!A:A) -> BATAM | AX8: LBJ | AY8: SUMBAGTENG | AZ8: BATAM | BA8: Batch 3 | BB8: 3 | BC8: 24 | BD8: PT HDUA PUTRA PRAJODA | BE8: 6. FINISH INSTALASI | BF8: 6.7 Belum Submit ABD | BG8: 26/02 Terminasi ODP dan Jumper FTM. 18/02 Izin di acc dengan catatan haru benjar jaringan eksisting. 16/02 Plan anwijzing 19 Feb. 11/02 Peralihan mitra. 28/01 Mitra tripola belum ada PIC untuk anwijzing. 23/01 Plan anwijzing 26 Jan, pic mitra ada pertanggal 25 jan. 21/01 proses penunjukan mitra 11/02 Peralihan mitra. 28/01 Mitra tripola belum ada PIC untuk anwijzing. 23/01 Plan anwijzing 26 Jan, pic mitra ada pertanggal 25 jan. 21/01 proses penunjukan mitra | BH8: MARET | BI8: 46086 | BK8: GOLIVE | BS8: BATAM | BT8: 1140 | BU8: =SUMIFS( 'PT2 UNTSEL 2026'!$AS:$AS, 'PT2 UNTSEL 2026'!$AF:$AF,"BATAM", 'PT2 UNTSEL 2026'!$AZ:$AZ,"GO LIVE", 'PT2 UNTSEL 2026'!$T:$T,">="&DATE(2026,3,1), 'PT2 UNTSEL 2026'!$T:$T,"<"&DATE(2026,4,1) ) -> 600 | BV8: =BU8/BT8 -> 0.52631579 | BW8: 2317 | BX8: ='REPORT GOLIVE JPP - OLO'!U7 -> 120 | BY8: =BX8/BW8 -> 0.051791109 | BZ8: =BT8+BW8 -> 3457 | CA8: =BU8+BX8 -> 720 | CB8: =CA8/BZ8 -> 0.20827307 | CD8: BATAM | CE8: 5430 | CF8: =SUMIFS( 'PT2 UNTSEL 2026'!$AS:$AS, 'PT2 UNTSEL 2026'!$AF:$AF,"BATAM", 'PT2 UNTSEL 2026'!$AZ:$AZ,"GO LIVE") -> 1896 | CG8: =CF8/CE8 -> 0.34917127 | CH8: 7276 | CI8: =SUMIFS(K4:K3194,H4:H3194,"batam",R4:R3194,"golive") -> 0 | CJ8: =CI8/CH8 -> 0 | CK8: =CE8+CH8 -> 12706 | CL8: =CF8+CI8 -> 1896 | CM8: =CL8/CK8 -> 0.14922084
A9: =IFERROR(__xludf.DUMMYFUNCTION("""COMPUTED_VALUE"""),2026.0) -> 2026 | B9: =IFERROR(__xludf.DUMMYFUNCTION("""COMPUTED_VALUE"""),1.1013283E7) -> 11013283 | C9: =IFERROR(__xludf.DUMMYFUNCTION("""COMPUTED_VALUE"""),"SMU KIS-FF D04 D05 SBU_RAP_ASAHAN KIS012") -> SMU KIS-FF D04 D05 SBU_RAP_ASAHAN KIS012 | D9: =IFERROR(__xludf.DUMMYFUNCTION("""COMPUTED_VALUE"""),"REGIONAL I") -> REGIONAL I | E9: =IFERROR(__xludf.DUMMYFUNCTION("""COMPUTED_VALUE"""),"SUMUT") -> SUMUT | F9: =IFERROR(__xludf.DUMMYFUNCTION("""COMPUTED_VALUE"""),"KIS") -> KIS | G9: =IFERROR(__xludf.DUMMYFUNCTION("""COMPUTED_VALUE"""),"SUMBAGUT") -> SUMBAGUT | H9: =IFERROR(__xludf.DUMMYFUNCTION("""COMPUTED_VALUE"""),"RANTAU PRAPAT") -> RANTAU PRAPAT | I9: =IFERROR(__xludf.DUMMYFUNCTION("""COMPUTED_VALUE"""),"Batch 1") -> Batch 1 | J9: =IFERROR(__xludf.DUMMYFUNCTION("""COMPUTED_VALUE"""),17.0) -> 17 | K9: =IFERROR(__xludf.DUMMYFUNCTION("""COMPUTED_VALUE"""),136.0) -> 136 | L9: =IFERROR(__xludf.DUMMYFUNCTION("""COMPUTED_VALUE"""),1141303.0) -> 1141303 | M9: =IFERROR(__xludf.DUMMYFUNCTION("""COMPUTED_VALUE"""),1.55217073E8) -> 155217073 | N9: =IFERROR(__xludf.DUMMYFUNCTION("""COMPUTED_VALUE"""),"PT GARINDO TECHNO MANDIRI") -> PT GARINDO TECHNO MANDIRI | O9: =IFERROR(__xludf.DUMMYFUNCTION("""COMPUTED_VALUE"""),"5. INSTALASI") -> 5. INSTALASI | P9: =IFERROR(__xludf.DUMMYFUNCTION("""COMPUTED_VALUE"""),"5.6 Proses Penarikan Kabel") -> 5.6 Proses Penarikan Kabel | Q9: =IFERROR(__xludf.DUMMYFUNCTION("""COMPUTED_VALUE"""),"27/4 proses penarikan kabel, 23/4 plan progres hari ini, 22/4 tim partial di lop kis fbc, 21/4 prepair tim pengambilan material, 20/4 prepair tim pengambilan material, 16/4 plan hari ini pengambilan material dari tebing, 15/4 prepair tim untuk pengambilan"&" material (pengalihan dari mitra mai), 14/4 prepair tim untuk pengambilan material (pengalihan dari mitra mai), 13/4 mitra MAI menolak untuk lanjut progres, 9/4 mitra MAI menolak untuk lanjut progres, 8/4 mitra MAI menolak untuk lanjut progres, 6/4 plan e"&"st progres delivery besok apabila belum kunjung dikerjakan maka lop kita alihkan kemitra lain, 5/4 tim belum turun untuk mengambil material, 1/4 tim belum turun untuk mengambil material, 31/3 tim belum turun untuk mengambil material, 30/3 plan pengambila"&"n material rabu 1 april, 27/3 hari ini proses pengambilan material kegudang, plan instalasi besok, 26/3 prepair team untuk pengambilan matrial dari wh ke site, 22/3 prepair team untuk pengambilan matrial dari wh ke site, 18/3 plan pengambilan matrial sete"&"lah lebaran, 16/3 plan pengambilan matrial setelah lebaran, 13/3 prepair tim untuk pengambilan material, 11/3 plan ambil matrial besok, 10/3 prepair tim untuk pengambilan material plan bsk tgl 11 maret, 6/3 prepair tim untuk pengambilan material, 5/3 prep"&"air tim untuk pengambilan material, 4/3 prepair tim untuk pengambilan material, 3/3 proses request material, 2/3 menunggu info dari pihak desa terkait izin tanam tiang dan peralihan rute, 27/2 menunggu info dari pihak desa terkait izin tanam tiang dan p"&"eralihan rute. 25/2 prepair team untuk delivery matrial dari gudang ke wh, 20/2 plan deliv matrial 23 feb ,19/2 prepair tim untuk pengambilan material, 18/2 prepair tim untuk pengambilan material,16/2 prepair tim untuk pengambilan material, 13/2 prepair "&"tim untuk pengambilan material, 11/2 peoses req material, 10/2 proses req material, 9/2 proses req material, 6/2 proses req material, 5/2 proses req matrial,4/2 proses req matrial, 3/2 proses cek cpp, 2/2 plan besok cek cpp hasil survey, 1/2 menunggu boq "&"kml hasil survey ( blm ada report survey dan hasil otdr), 30/1 menunggu boq kml hasil survey ( blm ada report survey dan hasil otdr), 28/1 menunggu boq kml hasil survey ( blm ada report survey dan hasil otdr), 27/1 menunggu boq kml hasil survey ( blm ada "&"report survey dan hasil otdr), 26/1 menunggu boq kml hasil survey ( blm ada report survey dan hasil otdr), 23/1 menunggu boq kml hasil survey, 22/1 menunggu boq kml survey, 21/1 menunggu boq kml survey, 20/1 plan survey 21/1, 19/1 plan survey 21/1, 15/1 "&"plan survey 21/1, 14/1 prepair tim untuk penjadwalan survey, 13/1 menunggu info kelanjutan dari mitra est besok 14/1, (07/01) Persiapan") -> 27/4 proses penarikan kabel, 23/4 plan progres hari ini, 22/4 tim partial di lop kis fbc, 21/4 prepair tim pengambilan material, 20/4 prepair tim pengambilan material, 16/4 plan hari ini pengambilan material dari tebing, 15/4 prepair tim untuk pengambilan material (pengalihan dari mitra mai), 14/4 prepair tim untuk pengambilan material (pengalihan dari mitra mai), 13/4 mitra MAI menolak untuk lanjut progres, 9/4 mitra MAI menolak untuk lanjut progres, 8/4 mitra MAI menolak untuk lanjut progres, 6/4 plan est progres delivery besok apabila belum kunjung dikerjakan maka lop kita alihkan kemitra lain, 5/4 tim belum turun untuk mengambil material, 1/4 tim belum turun untuk mengambil material, 31/3 tim belum turun untuk mengambil material, 30/3 plan pengambilan material rabu 1 april, 27/3 hari ini proses pengambilan material kegudang, plan instalasi besok, 26/3 prepair team untuk pengambilan matrial dari wh ke site, 22/3 prepair team untuk pengambilan matrial dari wh ke site, 18/3 plan pengambilan matrial setelah lebaran, 16/3 plan pengambilan matrial setelah lebaran, 13/3 prepair tim untuk pengambilan material, 11/3 plan ambil matrial besok, 10/3 prepair tim untuk pengambilan material plan bsk tgl 11 maret, 6/3 prepair tim untuk pengambilan material, 5/3 prepair tim untuk pengambilan material, 4/3 prepair tim untuk pengambilan material, 3/3 proses request material, 2/3 menunggu info dari pihak desa terkait izin tanam tiang dan peralihan rute, 27/2 menunggu info dari pihak desa terkait izin tanam tiang dan peralihan rute. 25/2 prepair team untuk delivery matrial dari gudang ke wh, 20/2 plan deliv matrial 23 feb ,19/2 prepair tim untuk pengambilan material, 18/2 prepair tim untuk pengambilan material,16/2 prepair tim untuk pengambilan material, 13/2 prepair tim untuk pengambilan material, 11/2 peoses req material, 10/2 proses req material, 9/2 proses req material, 6/2 proses req material, 5/2 proses req matrial,4/2 proses req matrial, 3/2 proses cek cpp, 2/2 plan besok cek cpp hasil survey, 1/2 menunggu boq kml hasil survey ( blm ada report survey dan hasil otdr), 30/1 menunggu boq kml hasil survey ( blm ada report survey dan hasil otdr), 28/1 menunggu boq kml hasil survey ( blm ada report survey dan hasil otdr), 27/1 menunggu boq kml hasil survey ( blm ada report survey dan hasil otdr), 26/1 menunggu boq kml hasil survey ( blm ada report survey dan hasil otdr), 23/1 menunggu boq kml hasil survey, 22/1 menunggu boq kml survey, 21/1 menunggu boq kml survey, 20/1 plan survey 21/1, 19/1 plan survey 21/1, 15/1 plan survey 21/1, 14/1 prepair tim untuk penjadwalan survey, 13/1 menunggu info kelanjutan dari mitra est besok 14/1, (07/01) Persiapan | R9: =IFERROR(__xludf.DUMMYFUNCTION("""COMPUTED_VALUE"""),46140.0) -> 46140 | U9: =IFERROR(__xludf.DUMMYFUNCTION("""COMPUTED_VALUE"""),"TIF-2851/2026") -> TIF-2851/2026 | W9: =IFERROR(__xludf.DUMMYFUNCTION("""COMPUTED_VALUE"""),"#REF!") -> #REF! | X9: =IFERROR(__xludf.DUMMYFUNCTION("""COMPUTED_VALUE"""),"BELUM GOLIVE") -> BELUM GOLIVE | Z9: =IFERROR(__xludf.DUMMYFUNCTION("""COMPUTED_VALUE"""),"#N/A") -> #N/A | AH9: 46140 | AI9: =IF(OR(R9="",AE9=""),"",R9-AE9) | AJ9: =if(AI9>=0,"not yet","lewat komitmen") -> not yet | AR9: 3 | AS9: 2026 | AT9: 11288505 | AU9: RDR JPP PT4 JL HARAPAN JAYA BAGAN BATU | AV9: REGIONAL I | AW9: =xlookup(AX9,BANTU!B:B,BANTU!A:A) -> DUMAI | AX9: BGU | AY9: SUMBAGTENG | AZ9: DUMAI | BA9: Batch 3 | BB9: 18 | BC9: 144 | BD9: PT DWI MITRA JAYA UTAMA | BE9: 6. FINISH INSTALASI | BF9: 6.3 Kendala OLT / Mini OLT / OTN | BG9: 12/02 Menunggu Mini OLT UJT666 29/01 Terminasi ODP | BH9: MARET | BI9: 46087 | BL9: 144
A10: =IFERROR(__xludf.DUMMYFUNCTION("""COMPUTED_VALUE"""),2026.0) -> 2026 | B10: =IFERROR(__xludf.DUMMYFUNCTION("""COMPUTED_VALUE"""),1.1093003E7) -> 11093003 | C10: =IFERROR(__xludf.DUMMYFUNCTION("""COMPUTED_VALUE"""),"SMU TJB-FAP D02-D04 CLUST ASAHAN TJB006") -> SMU TJB-FAP D02-D04 CLUST ASAHAN TJB006 | D10: =IFERROR(__xludf.DUMMYFUNCTION("""COMPUTED_VALUE"""),"REGIONAL I") -> REGIONAL I | E10: =IFERROR(__xludf.DUMMYFUNCTION("""COMPUTED_VALUE"""),"SUMUT") -> SUMUT | F10: =IFERROR(__xludf.DUMMYFUNCTION("""COMPUTED_VALUE"""),"TJB") -> TJB | G10: =IFERROR(__xludf.DUMMYFUNCTION("""COMPUTED_VALUE"""),"SUMBAGUT") -> SUMBAGUT | H10: =IFERROR(__xludf.DUMMYFUNCTION("""COMPUTED_VALUE"""),"RANTAU PRAPAT") -> RANTAU PRAPAT | I10: =IFERROR(__xludf.DUMMYFUNCTION("""COMPUTED_VALUE"""),"Batch 1") -> Batch 1 | J10: =IFERROR(__xludf.DUMMYFUNCTION("""COMPUTED_VALUE"""),9.0) -> 9 | K10: =IFERROR(__xludf.DUMMYFUNCTION("""COMPUTED_VALUE"""),72.0) -> 72 | L10: =IFERROR(__xludf.DUMMYFUNCTION("""COMPUTED_VALUE"""),1300795.0) -> 1300795 | M10: =IFERROR(__xludf.DUMMYFUNCTION("""COMPUTED_VALUE"""),9.3657216E7) -> 93657216 | N10: =IFERROR(__xludf.DUMMYFUNCTION("""COMPUTED_VALUE"""),"PT ARTHA MANDIRI BERSAMA") -> PT ARTHA MANDIRI BERSAMA | O10: =IFERROR(__xludf.DUMMYFUNCTION("""COMPUTED_VALUE"""),"7. GOLIVE") -> 7. GOLIVE | P10: =IFERROR(__xludf.DUMMYFUNCTION("""COMPUTED_VALUE"""),"7.2 Golive Full / OA / DONE OTB") -> 7.2 Golive Full / OA / DONE OTB | Q10: =IFERROR(__xludf.DUMMYFUNCTION("""COMPUTED_VALUE"""),"27/4 proses validasi sdi, 23/4 sisa inrtal dan terminasi 9 odp, penarikan ku 12 (2635 selesai) tanam tiang 20 selesai, , 22/4 penarikan ku 12 (2635 selesai) tanam tiang 20 selesai, odp 9 sisa 6, 21/4 penarikan ku 12 (2635 sisa 1335) tanam tiang 20 sisa 5"&", odp 9 blm ada progres, 20/04 progres penanaman tiang 16/5 plan ambil material sabtu tgl 18 april, 15/4 prepair tim untuk pengambilan material, pararel perizinan ke perumahan, 14/4 proses input material di alista, pararel perizinan ke perumahan, 13/4 pro"&"ses input di alista, pararel perizinan ke perumahan, 9/4 cpp tinggi 1,4, 8/4 menunggu submit boq kml hasil survey, pararel perizinan ke perumahan Duta Mas Indah, 6/4 plan survey hari 6 april (hasil survey mitra sebelumnya biaya prelim 11 jt), 5/4 plan s"&"urvey senin 6 april (hasil survey mitra sebelumnya biaya prelim 11 jt), 1/4 plan survey kamis 2 april (hasil survey mitra sebelumnya biaya prelim 11 jt), 31/3 plan survey rabu 1 april (hasil survey mitra sebelumnya biaya prelim 11 jt ), 27/3 plan survey s"&"enin 30 maret (hasil survey mitra sebelumnya biaya prelim 11 jt ), 26/3 menunggu boq kml terbaru dari sdi, 22/3 menunggu boq kml terbaru dari sdi, 18/3 plan survey setelah lebaran , 16/3 plan survey setelah lebaran , 26/2 drop dikarenakan prelim ke desa 1"&"1 jt, drop permintaan tsel ( cpp 11 jt), (07/01) Persiapan") -> 27/4 proses validasi sdi, 23/4 sisa inrtal dan terminasi 9 odp, penarikan ku 12 (2635 selesai) tanam tiang 20 selesai, , 22/4 penarikan ku 12 (2635 selesai) tanam tiang 20 selesai, odp 9 sisa 6, 21/4 penarikan ku 12 (2635 sisa 1335) tanam tiang 20 sisa 5, odp 9 blm ada progres, 20/04 progres penanaman tiang 16/5 plan ambil material sabtu tgl 18 april, 15/4 prepair tim untuk pengambilan material, pararel perizinan ke perumahan, 14/4 proses input material di alista, pararel perizinan ke perumahan, 13/4 proses input di alista, pararel perizinan ke perumahan, 9/4 cpp tinggi 1,4, 8/4 menunggu submit boq kml hasil survey, pararel perizinan ke perumahan Duta Mas Indah, 6/4 plan survey hari 6 april (hasil survey mitra sebelumnya biaya prelim 11 jt), 5/4 plan survey senin 6 april (hasil survey mitra sebelumnya biaya prelim 11 jt), 1/4 plan survey kamis 2 april (hasil survey mitra sebelumnya biaya prelim 11 jt), 31/3 plan survey rabu 1 april (hasil survey mitra sebelumnya biaya prelim 11 jt ), 27/3 plan survey senin 30 maret (hasil survey mitra sebelumnya biaya prelim 11 jt ), 26/3 menunggu boq kml terbaru dari sdi, 22/3 menunggu boq kml terbaru dari sdi, 18/3 plan survey setelah lebaran , 16/3 plan survey setelah lebaran , 26/2 drop dikarenakan prelim ke desa 11 jt, drop permintaan tsel ( cpp 11 jt), (07/01) Persiapan | R10: =IFERROR(__xludf.DUMMYFUNCTION("""COMPUTED_VALUE"""),46139.0) -> 46139 | S10: =IFERROR(__xludf.DUMMYFUNCTION("""COMPUTED_VALUE"""),"APR") -> APR | U10: =IFERROR(__xludf.DUMMYFUNCTION("""COMPUTED_VALUE"""),"W03-2261/2024") -> W03-2261/2024 | V10: =IFERROR(__xludf.DUMMYFUNCTION("""COMPUTED_VALUE"""),"29/Apr/2026") -> 29/Apr/2026 | X10: =IFERROR(__xludf.DUMMYFUNCTION("""COMPUTED_VALUE"""),"GOLIVE") -> GOLIVE | Y10: =IFERROR(__xludf.DUMMYFUNCTION("""COMPUTED_VALUE"""),"DONE") -> DONE | Z10: =IFERROR(__xludf.DUMMYFUNCTION("""COMPUTED_VALUE"""),"#N/A") -> #N/A | AA10: =IFERROR(__xludf.DUMMYFUNCTION("""COMPUTED_VALUE"""),9.0) -> 9 | AC10: =IFERROR(__xludf.DUMMYFUNCTION("""COMPUTED_VALUE"""),"9313750#9313755") -> 9313750#9313755 | AD10: =IFERROR(__xludf.DUMMYFUNCTION("""COMPUTED_VALUE"""),72.0) -> 72 | AE10: =IFERROR(__xludf.DUMMYFUNCTION("""COMPUTED_VALUE"""),46139.0) -> 46139 | AF10: =IFERROR(__xludf.DUMMYFUNCTION("""COMPUTED_VALUE"""),"Draft BA DROP") -> Draft BA DROP | AI10: =IF(OR(R10="",AE10=""),"",R10-AE10) -> 0 | AJ10: =if(AI10>=0,"not yet","lewat komitmen") -> not yet | AR10: 4 | AS10: 2026 | AT10: 12494439 | AU10: RDR JPP PT3 250_184_2904 | AV10: REGIONAL I | AW10: =xlookup(AX10,BANTU!B:B,BANTU!A:A) -> PEKANBARU | AX10: BKR | AY10: SUMBAGTENG | AZ10: PEKANBARU | BA10: Batch 3 | BB10: 12 | BC10: 96 | BD10: PT TIGA AKSES MANDIRI | BE10: 5. INSTALASI | BF10: 5.6 Proses Penarikan Kabel | BG10: 04/03 Pekerjaan sudah lanjut penarikan kabel 20/02 Pekerjaan di stop oleh warga setempat 10/02 Pengitiman material ke Lokasi 29/01 Antrian review hasil anwidzing | BH10: MARET | BI10: 46088 | BK10: GOLIVE | BL10: 136 | BS10: BUKIT TINGGI | BT10: 855 | BU10: =SUMIFS( 'PT2 UNTSEL 2026'!$AS:$AS, 'PT2 UNTSEL 2026'!$AF:$AF,"Bukit tinggi", 'PT2 UNTSEL 2026'!$AZ:$AZ,"GO LIVE", 'PT2 UNTSEL 2026'!$T:$T,">="&DATE(2026,3,1), 'PT2 UNTSEL 2026'!$T:$T,"<"&DATE(2026,4,1) ) -> 72 | BV10: =BU10/BT10 -> 0.084210526 | BW10: 5298 | BX10: ='REPORT GOLIVE JPP - OLO'!U9 -> 272 | BY10: =BX10/BW10 -> 0.051340128 | BZ10: =BT10+BW10 -> 6153 | CA10: =BU10+BX10 -> 344 | CB10: =CA10/BZ10 -> 0.055907687 | CD10: BUKIT TINGGI | CE10: 4073 | CF10: =SUMIFS( 'PT2 UNTSEL 2026'!$AS:$AS, 'PT2 UNTSEL 2026'!$AF:$AF,"Bukit tinggi", 'PT2 UNTSEL 2026'!$AZ:$AZ,"GO LIVE") -> 248 | CG10: =CF10/CE10 -> 0.06088878 | CH10: 16636 | CI10: =SUMIFS(K6:K3194,H6:H3194,"bukit tinggi",R6:R3194,"golive") -> 0 | CJ10: =CI10/CH10 -> 0 | CK10: =CE10+CH10 -> 20709 | CL10: =CF10+CI10 -> 248 | CM10: =CL10/CK10 -> 0.01197547
A11: =IFERROR(__xludf.DUMMYFUNCTION("""COMPUTED_VALUE"""),2026.0) -> 2026 | B11: =IFERROR(__xludf.DUMMYFUNCTION("""COMPUTED_VALUE"""),1.1098751E7) -> 11098751 | C11: =IFERROR(__xludf.DUMMYFUNCTION("""COMPUTED_VALUE"""),"SMU P7I1 ODC-GNT-FAK CLUST ULU GAJAH.") -> SMU P7I1 ODC-GNT-FAK CLUST ULU GAJAH. | D11: =IFERROR(__xludf.DUMMYFUNCTION("""COMPUTED_VALUE"""),"REGIONAL I") -> REGIONAL I | E11: =IFERROR(__xludf.DUMMYFUNCTION("""COMPUTED_VALUE"""),"SUMUT") -> SUMUT | F11: =IFERROR(__xludf.DUMMYFUNCTION("""COMPUTED_VALUE"""),"GNT") -> GNT | G11: =IFERROR(__xludf.DUMMYFUNCTION("""COMPUTED_VALUE"""),"SUMBAGUT") -> SUMBAGUT | H11: =IFERROR(__xludf.DUMMYFUNCTION("""COMPUTED_VALUE"""),"RANTAU PRAPAT") -> RANTAU PRAPAT | I11: =IFERROR(__xludf.DUMMYFUNCTION("""COMPUTED_VALUE"""),"Batch 1") -> Batch 1 | J11: =IFERROR(__xludf.DUMMYFUNCTION("""COMPUTED_VALUE"""),30.0) -> 30 | K11: =IFERROR(__xludf.DUMMYFUNCTION("""COMPUTED_VALUE"""),240.0) -> 240 | L11: =IFERROR(__xludf.DUMMYFUNCTION("""COMPUTED_VALUE"""),1466140.0) -> 1466140 | M11: =IFERROR(__xludf.DUMMYFUNCTION("""COMPUTED_VALUE"""),3.51873529E8) -> 351873529 | N11: =IFERROR(__xludf.DUMMYFUNCTION("""COMPUTED_VALUE"""),"PT SANGKURIANG CIPTA JAYA TEKNINDO") -> PT SANGKURIANG CIPTA JAYA TEKNINDO | O11: =IFERROR(__xludf.DUMMYFUNCTION("""COMPUTED_VALUE"""),"0. DROP") -> 0. DROP | P11: =IFERROR(__xludf.DUMMYFUNCTION("""COMPUTED_VALUE"""),"0.2 Tidak Dapat Izin Warga/Kades/Lurah/Developer") -> 0.2 Tidak Dapat Izin Warga/Kades/Lurah/Developer | Q11: =IFERROR(__xludf.DUMMYFUNCTION("""COMPUTED_VALUE"""),"drop karena tidak ada nim order, drop kendala project fo PSP584 drop,, (07/01) Persiapan") -> drop karena tidak ada nim order, drop kendala project fo PSP584 drop,, (07/01) Persiapan | U11: =IFERROR(__xludf.DUMMYFUNCTION("""COMPUTED_VALUE"""),"W03-2366/2024") -> W03-2366/2024 | X11: =IFERROR(__xludf.DUMMYFUNCTION("""COMPUTED_VALUE"""),"BELUM GOLIVE") -> BELUM GOLIVE | Z11: =IFERROR(__xludf.DUMMYFUNCTION("""COMPUTED_VALUE"""),"#N/A") -> #N/A | AF11: =IFERROR(__xludf.DUMMYFUNCTION("""COMPUTED_VALUE"""),"Draft BA DROP") -> Draft BA DROP | AI11: =IF(OR(R11="",AE11=""),"",R11-AE11) | AJ11: =if(AI11>=0,"not yet","lewat komitmen") -> not yet | AR11: 5 | AS11: 2026 | AT11: 12687799 | AU11: RDR JPP PT3 250_200_2865 | AV11: REGIONAL I | AW11: =xlookup(AX11,BANTU!B:B,BANTU!A:A) -> PEKANBARU | AX11: ARK | AY11: SUMBAGTENG | AZ11: PEKANBARU | BA11: Batch 3 | BB11: 5 | BC11: 40 | BD11: PT UPAYA TEKNIK | BE11: 5. INSTALASI | BF11: 5.4 Proses Penanaman Tiang | BH11: MARET | BI11: 46088 | BK11: GOLIVE
A12: =IFERROR(__xludf.DUMMYFUNCTION("""COMPUTED_VALUE"""),2026.0) -> 2026 | B12: =IFERROR(__xludf.DUMMYFUNCTION("""COMPUTED_VALUE"""),1.1113042E7) -> 11113042 | C12: =IFERROR(__xludf.DUMMYFUNCTION("""COMPUTED_VALUE"""),"SMU-ODC-KBJ-FAE SUMUT_233") -> SMU-ODC-KBJ-FAE SUMUT_233 | D12: =IFERROR(__xludf.DUMMYFUNCTION("""COMPUTED_VALUE"""),"REGIONAL I") -> REGIONAL I | E12: =IFERROR(__xludf.DUMMYFUNCTION("""COMPUTED_VALUE"""),"SUMUT") -> SUMUT | F12: =IFERROR(__xludf.DUMMYFUNCTION("""COMPUTED_VALUE"""),"KBJ") -> KBJ | G12: =IFERROR(__xludf.DUMMYFUNCTION("""COMPUTED_VALUE"""),"SUMBAGUT") -> SUMBAGUT | H12: =IFERROR(__xludf.DUMMYFUNCTION("""COMPUTED_VALUE"""),"PEMATANG SIANTAR") -> PEMATANG SIANTAR | I12: =IFERROR(__xludf.DUMMYFUNCTION("""COMPUTED_VALUE"""),"Batch 1") -> Batch 1 | J12: =IFERROR(__xludf.DUMMYFUNCTION("""COMPUTED_VALUE"""),7.0) -> 7 | K12: =IFERROR(__xludf.DUMMYFUNCTION("""COMPUTED_VALUE"""),56.0) -> 56 | L12: =IFERROR(__xludf.DUMMYFUNCTION("""COMPUTED_VALUE"""),686751.0) -> 686751 | M12: =IFERROR(__xludf.DUMMYFUNCTION("""COMPUTED_VALUE"""),3.8458009E7) -> 38458009 | N12: =IFERROR(__xludf.DUMMYFUNCTION("""COMPUTED_VALUE"""),"PT GARINDO TECHNO MANDIRI") -> PT GARINDO TECHNO MANDIRI | O12: =IFERROR(__xludf.DUMMYFUNCTION("""COMPUTED_VALUE"""),"5. INSTALASI") -> 5. INSTALASI | P12: =IFERROR(__xludf.DUMMYFUNCTION("""COMPUTED_VALUE"""),"5.4 Proses Penanaman Tiang") -> 5.4 Proses Penanaman Tiang | Q12: =IFERROR(__xludf.DUMMYFUNCTION("""COMPUTED_VALUE"""),"27/4 proses tanam tiang 17 batang, ku 12 (750 belum progres, odp 7 belum progres, 24/4 (kenaikan nilai diatas 10 % dikarnakan ada nya perubahan titik plan brenching yg tidak sesuai dengan lapangan ) tim partial di lop kis ff, plan progres 25 april, 23/4 "&"(kenaikan nilai diatas 10 % dikarnakan ada nya perubahan titik plan brenching yg tidak sesuai dengan lapangan ) tim partial di lop kis ff, plan progres 25 april, 22/4 tim partial di lop kis ff, 21/4 tim partial di lop sdk fac, 20/4 prepair tim untuk ambi"&"l material tim partial di lop bst-fb, 16/4 plan pengambilan material jumat tgl 16 april, 15/4 plan pengambilan material jumat tgl 16 april, 14/4 plan pengambilan material jumat tgl 16 april, 13/4 proses input material di alista, , 9/4 menunggu boq kml sur"&"vey dari mitra, 8/4 menunggu boq kml survey dari mitra, 6/4 plan submit boq kml survey hari ini, 5/4 menunggu boq kml survey (port mini olt full), 1/4 menunggu boq kml survey ( port mini olt full), 31/3 menunggu boq kml survey ( port mini olt full), 30/3 "&"menunggu boq kml survey ( port mini olt full), 27/3 menunggu boq kml survey ( port mini olt full), 26/3 menunggu boq kml survey ( port mini olt full), 22/3 menunggu boq kml survey ( port mini olt full), 18/3 plan survey seletal lebaran, 16/3 plan besok s"&"urvey 17 maret, 13/3 prepair tim untuk melakukan survey, 11/3 prepair tim untuk melakukan survey, 10/3 plan survey bsk tgl 11 maret, 6/3 plan bsk tgl 9 februari untuk melakukan survey, 5/3 plan bsk tgl 6 februari untuk melakukan survey, 4/3 plan bsk 5 f"&"ebruari untuk melakukan survey, 3/3 prepair team untuk jadwal survey, 2/3 prepair team untuk jadwal survey , 27/2 prepair tim untuk survey plan tgl 28/2 , 25/2 prepair tim untuk survey plan tgl 28/2 , 24/2 prepair team untuk suvrey kelokasi, 23/2 prepa"&"ir team untuk suvrey kelokasi, 20/2 prepair team untuk suvrey kelokasi, 19/2 Mandor swakelola, 16/2 Mandor swakelola, 13/2 Mandor swakelola, 12/2 Mandor swakelola, 11/2 Mandor swakelola, 10/2 Mandor swakelola, 9/2 Mandor swakelola, 6/2 Mandor swakelola,"&" 5/2 Mandor swakelola, 4/2 Mandor swakelola, 3/2 Mandor swakelola, 2/2 Mandor swakelola, 1/2 Mandor swakelola, 30/1 Mandor swakelola , 28/1 Mandor swakelola, 27/1 Mandor swakelola, 26/1 prepair team untuk surveysurvey kelokasi, 23/1 ogp survey,22/1 plan "&"survey 23/1, 21/1 plan survey 23/1, 20/1 plan survey 23/1, 19/1 plan survey hari ini 19/1, 15/1 plan survey 19/1, 14/1 plan survey 23/1, 13/1 prepair team untuk penjadwalan survey, (07/01) Persiapan") -> 27/4 proses tanam tiang 17 batang, ku 12 (750 belum progres, odp 7 belum progres, 24/4 (kenaikan nilai diatas 10 % dikarnakan ada nya perubahan titik plan brenching yg tidak sesuai dengan lapangan ) tim partial di lop kis ff, plan progres 25 april, 23/4 (kenaikan nilai diatas 10 % dikarnakan ada nya perubahan titik plan brenching yg tidak sesuai dengan lapangan ) tim partial di lop kis ff, plan progres 25 april, 22/4 tim partial di lop kis ff, 21/4 tim partial di lop sdk fac, 20/4 prepair tim untuk ambil material tim partial di lop bst-fb, 16/4 plan pengambilan material jumat tgl 16 april, 15/4 plan pengambilan material jumat tgl 16 april, 14/4 plan pengambilan material jumat tgl 16 april, 13/4 proses input material di alista, , 9/4 menunggu boq kml survey dari mitra, 8/4 menunggu boq kml survey dari mitra, 6/4 plan submit boq kml survey hari ini, 5/4 menunggu boq kml survey (port mini olt full), 1/4 menunggu boq kml survey ( port mini olt full), 31/3 menunggu boq kml survey ( port mini olt full), 30/3 menunggu boq kml survey ( port mini olt full), 27/3 menunggu boq kml survey ( port mini olt full), 26/3 menunggu boq kml survey ( port mini olt full), 22/3 menunggu boq kml survey ( port mini olt full), 18/3 plan survey seletal lebaran, 16/3 plan besok survey 17 maret, 13/3 prepair tim untuk melakukan survey, 11/3 prepair tim untuk melakukan survey, 10/3 plan survey bsk tgl 11 maret, 6/3 plan bsk tgl 9 februari untuk melakukan survey, 5/3 plan bsk tgl 6 februari untuk melakukan survey, 4/3 plan bsk 5 februari untuk melakukan survey, 3/3 prepair team untuk jadwal survey, 2/3 prepair team untuk jadwal survey , 27/2 prepair tim untuk survey plan tgl 28/2 , 25/2 prepair tim untuk survey plan tgl 28/2 , 24/2 prepair team untuk suvrey kelokasi, 23/2 prepair team untuk suvrey kelokasi, 20/2 prepair team untuk suvrey kelokasi, 19/2 Mandor swakelola, 16/2 Mandor swakelola, 13/2 Mandor swakelola, 12/2 Mandor swakelola, 11/2 Mandor swakelola, 10/2 Mandor swakelola, 9/2 Mandor swakelola, 6/2 Mandor swakelola, 5/2 Mandor swakelola, 4/2 Mandor swakelola, 3/2 Mandor swakelola, 2/2 Mandor swakelola, 1/2 Mandor swakelola, 30/1 Mandor swakelola , 28/1 Mandor swakelola, 27/1 Mandor swakelola, 26/1 prepair team untuk surveysurvey kelokasi, 23/1 ogp survey,22/1 plan survey 23/1, 21/1 plan survey 23/1, 20/1 plan survey 23/1, 19/1 plan survey hari ini 19/1, 15/1 plan survey 19/1, 14/1 plan survey 23/1, 13/1 prepair team untuk penjadwalan survey, (07/01) Persiapan | R12: =IFERROR(__xludf.DUMMYFUNCTION("""COMPUTED_VALUE"""),46142.0) -> 46142 | T12: =IFERROR(__xludf.DUMMYFUNCTION("""COMPUTED_VALUE"""),"P1") -> P1 | U12: =IFERROR(__xludf.DUMMYFUNCTION("""COMPUTED_VALUE"""),"TIF-1406/2026") -> TIF-1406/2026 | V12: =IFERROR(__xludf.DUMMYFUNCTION("""COMPUTED_VALUE"""),"28/Apr/2026") -> 28/Apr/2026 | X12: =IFERROR(__xludf.DUMMYFUNCTION("""COMPUTED_VALUE"""),"BELUM GOLIVE") -> BELUM GOLIVE | Y12: =IFERROR(__xludf.DUMMYFUNCTION("""COMPUTED_VALUE"""),"Mini OLT Not Ready") -> Mini OLT Not Ready | Z12: =IFERROR(__xludf.DUMMYFUNCTION("""COMPUTED_VALUE"""),"#N/A") -> #N/A | AI12: =IF(OR(R12="",AE12=""),"",R12-AE12) | AJ12: =if(AI12>=0,"not yet","lewat komitmen") -> not yet | AR12: 6 | AS12: 2026 | AT12: 12742254 | AU12: SMB-PT3-ODC-SIG-FA-150527-63694-36373 | AV12: REGIONAL I | AW12: =xlookup(AX12,BANTU!B:B,BANTU!A:A) -> BUKIT TINGGI | AX12: SIG | AY12: SUMBAGTENG | AZ12: BUKIT TINGGI | BA12: Batch 3 | BB12: 6 | BC12: 48 | BD12: PT TSUIKA BERKAH RAYA | BE12: 6. FINISH INSTALASI | BF12: 6.8 Sudah Submit ABD ke SDI | BG12: (05/03) ABD done submit ke sdi (02/03) ABD OGP submit ke sdi (18/02) Tanam tiang plan FI 21/02 (03/02) Proses create PID (29/01) Done aanwijziing , proses eval | BH12: MARET | BI12: 46089 | BK12: GOLIVE | BL12: 96 | BS12: DUMAI | BT12: 855 | BU12: =SUMIFS( 'PT2 UNTSEL 2026'!$AS:$AS, 'PT2 UNTSEL 2026'!$AF:$AF,"dumai", 'PT2 UNTSEL 2026'!$AZ:$AZ,"GO LIVE", 'PT2 UNTSEL 2026'!$T:$T,">="&DATE(2026,3,1), 'PT2 UNTSEL 2026'!$T:$T,"<"&DATE(2026,4,1) ) -> 56 | BV12: =BU12/BT12 -> 0.065497076 | BW12: 9777 | BX12: ='REPORT GOLIVE JPP - OLO'!U11 -> 688 | BY12: =BX12/BW12 -> 0.070369234 | BZ12: =BT12+BW12 -> 10632 | CA12: =BU12+BX12 -> 744 | CB12: =CA12/BZ12 -> 0.069977427 | CD12: DUMAI | CE12: 4073 | CF12: =SUMIFS( 'PT2 UNTSEL 2026'!$AS:$AS, 'PT2 UNTSEL 2026'!$AF:$AF,"dumai", 'PT2 UNTSEL 2026'!$AZ:$AZ,"GO LIVE") -> 736 | CG12: =CF12/CE12 -> 0.18070219 | CH12: 30701 | CI12: =SUMIFS(K8:K3194,H8:H3194,"dumai",R8:R3194,"golive") -> 0 | CJ12: =CI12/CH12 -> 0 | CK12: =CE12+CH12 -> 34774 | CL12: =CF12+CI12 -> 736 | CM12: =CL12/CK12 -> 0.021165238
A13: =IFERROR(__xludf.DUMMYFUNCTION("""COMPUTED_VALUE"""),2026.0) -> 2026 | B13: =IFERROR(__xludf.DUMMYFUNCTION("""COMPUTED_VALUE"""),1.1149875E7) -> 11149875 | C13: =IFERROR(__xludf.DUMMYFUNCTION("""COMPUTED_VALUE"""),"SMU KPI-FAL CLUST PERUM GRIYA FATIH") -> SMU KPI-FAL CLUST PERUM GRIYA FATIH | D13: =IFERROR(__xludf.DUMMYFUNCTION("""COMPUTED_VALUE"""),"REGIONAL I") -> REGIONAL I | E13: =IFERROR(__xludf.DUMMYFUNCTION("""COMPUTED_VALUE"""),"SUMUT") -> SUMUT | F13: =IFERROR(__xludf.DUMMYFUNCTION("""COMPUTED_VALUE"""),"KPI") -> KPI | G13: =IFERROR(__xludf.DUMMYFUNCTION("""COMPUTED_VALUE"""),"SUMBAGUT") -> SUMBAGUT | H13: =IFERROR(__xludf.DUMMYFUNCTION("""COMPUTED_VALUE"""),"RANTAU PRAPAT") -> RANTAU PRAPAT | I13: =IFERROR(__xludf.DUMMYFUNCTION("""COMPUTED_VALUE"""),"Batch 1") -> Batch 1 | J13: =IFERROR(__xludf.DUMMYFUNCTION("""COMPUTED_VALUE"""),7.0) -> 7 | K13: =IFERROR(__xludf.DUMMYFUNCTION("""COMPUTED_VALUE"""),56.0) -> 56 | L13: =IFERROR(__xludf.DUMMYFUNCTION("""COMPUTED_VALUE"""),600453.0) -> 600453 | M13: =IFERROR(__xludf.DUMMYFUNCTION("""COMPUTED_VALUE"""),3.3625353E7) -> 33625353 | N13: =IFERROR(__xludf.DUMMYFUNCTION("""COMPUTED_VALUE"""),"PT PRIMA INDO SENTOSA") -> PT PRIMA INDO SENTOSA | O13: =IFERROR(__xludf.DUMMYFUNCTION("""COMPUTED_VALUE"""),"0. DROP") -> 0. DROP | P13: =IFERROR(__xludf.DUMMYFUNCTION("""COMPUTED_VALUE"""),"0.2 Tidak Dapat Izin Warga/Kades/Lurah/Developer") -> 0.2 Tidak Dapat Izin Warga/Kades/Lurah/Developer | Q13: =IFERROR(__xludf.DUMMYFUNCTION("""COMPUTED_VALUE"""),"drop tidak dapat ijin pihak developer) (07/01) Persiapan") -> drop tidak dapat ijin pihak developer) (07/01) Persiapan | U13: =IFERROR(__xludf.DUMMYFUNCTION("""COMPUTED_VALUE"""),"DROP") -> DROP | X13: =IFERROR(__xludf.DUMMYFUNCTION("""COMPUTED_VALUE"""),"BELUM GOLIVE") -> BELUM GOLIVE | Z13: =IFERROR(__xludf.DUMMYFUNCTION("""COMPUTED_VALUE"""),"#N/A") -> #N/A | AF13: =IFERROR(__xludf.DUMMYFUNCTION("""COMPUTED_VALUE"""),"Draft BA DROP") -> Draft BA DROP | AI13: =IF(OR(R13="",AE13=""),"",R13-AE13) | AJ13: =if(AI13>=0,"not yet","lewat komitmen") -> not yet | AR13: 7 | AS13: 2026 | AT13: 11202007 | AU13: RKP PT3 TSEL BUM-FJ GG. APEL TJ. BUNTUNG | AV13: REGIONAL I | AW13: =xlookup(AX13,BANTU!B:B,BANTU!A:A) -> BATAM | AX13: BUM | AY13: SUMBAGTENG | AZ13: BATAM | BA13: Batch 2 | BB13: 2 | BC13: 16 | BD13: PT TRIPOLA PANATA | BE13: 5. INSTALASI | BF13: 5.9 Proses Pemasangan/Terminasi ODP/OTB | BG13: 18/02 Fi tanggal 24 Feb, Sumbit ABD tanggal 25 Feb. 09/02 Proses terminasi. 04/02 Proses tarik kabel, plan FI tanggal 07. 30/01 Tanam tiang. 28/01 Deliv material, Plan tanam tiang tgl 29, tarik kabel 30, Terminasi dan ABD mancore tanggal 31 | BH13: MARET | BI13: 46089 | BK13: GOLIVE | BO13: TARGET | BP13: =BB3 -> 8 | BQ13: =BC3 -> 64
A14: =IFERROR(__xludf.DUMMYFUNCTION("""COMPUTED_VALUE"""),2026.0) -> 2026 | B14: =IFERROR(__xludf.DUMMYFUNCTION("""COMPUTED_VALUE"""),1.1170704E7) -> 11170704 | C14: =IFERROR(__xludf.DUMMYFUNCTION("""COMPUTED_VALUE"""),"SMU TBT-FC D04 CLUST TAMBANGAN HULU") -> SMU TBT-FC D04 CLUST TAMBANGAN HULU | D14: =IFERROR(__xludf.DUMMYFUNCTION("""COMPUTED_VALUE"""),"REGIONAL I") -> REGIONAL I | E14: =IFERROR(__xludf.DUMMYFUNCTION("""COMPUTED_VALUE"""),"SUMUT") -> SUMUT | F14: =IFERROR(__xludf.DUMMYFUNCTION("""COMPUTED_VALUE"""),"TBT") -> TBT | G14: =IFERROR(__xludf.DUMMYFUNCTION("""COMPUTED_VALUE"""),"SUMBAGUT") -> SUMBAGUT | H14: =IFERROR(__xludf.DUMMYFUNCTION("""COMPUTED_VALUE"""),"PEMATANG SIANTAR") -> PEMATANG SIANTAR | I14: =IFERROR(__xludf.DUMMYFUNCTION("""COMPUTED_VALUE"""),"Batch 1") -> Batch 1 | J14: =IFERROR(__xludf.DUMMYFUNCTION("""COMPUTED_VALUE"""),2.0) -> 2 | K14: =IFERROR(__xludf.DUMMYFUNCTION("""COMPUTED_VALUE"""),16.0) -> 16 | L14: =IFERROR(__xludf.DUMMYFUNCTION("""COMPUTED_VALUE"""),331915.0) -> 331915 | M14: =IFERROR(__xludf.DUMMYFUNCTION("""COMPUTED_VALUE"""),5310626.0) -> 5310626 | N14: =IFERROR(__xludf.DUMMYFUNCTION("""COMPUTED_VALUE"""),"PT INTI SUKSES") -> PT INTI SUKSES | O14: =IFERROR(__xludf.DUMMYFUNCTION("""COMPUTED_VALUE"""),"0. DROP") -> 0. DROP | P14: =IFERROR(__xludf.DUMMYFUNCTION("""COMPUTED_VALUE"""),"0.1 Double Order") -> 0.1 Double Order | Q14: =IFERROR(__xludf.DUMMYFUNCTION("""COMPUTED_VALUE"""),"drop sudah kordinasi dengan TIF kendala sudah tercover project pt2 simple di titik yg sama . (07/01) Persiapan") -> drop sudah kordinasi dengan TIF kendala sudah tercover project pt2 simple di titik yg sama . (07/01) Persiapan | U14: =IFERROR(__xludf.DUMMYFUNCTION("""COMPUTED_VALUE"""),"W03-344/2025") -> W03-344/2025 | X14: =IFERROR(__xludf.DUMMYFUNCTION("""COMPUTED_VALUE"""),"BELUM GOLIVE") -> BELUM GOLIVE | Z14: =IFERROR(__xludf.DUMMYFUNCTION("""COMPUTED_VALUE"""),"#N/A") -> #N/A | AF14: =IFERROR(__xludf.DUMMYFUNCTION("""COMPUTED_VALUE"""),"Draft BA DROP") -> Draft BA DROP | AI14: =IF(OR(R14="",AE14=""),"",R14-AE14) | AJ14: =if(AI14>=0,"not yet","lewat komitmen") -> not yet | AR14: 8 | AS14: 2026 | AT14: 11902804 | AU14: RKP TSEL PT3 SLU-FAS KOTA BATAM_18520 | AV14: REGIONAL I | AW14: =xlookup(AX14,BANTU!B:B,BANTU!A:A) -> BATAM | AX14: SLU | AY14: SUMBAGTENG | AZ14: BATAM | BA14: Batch 2 | BB14: 1 | BC14: 8 | BD14: PT MITRA HOSINDO SEJAHTERA | BE14: 4. MATDEL | BF14: 4.1 Belum Request Material (Alista) | BG14: 16/02 CPP eval OK, progres deliv material. 11/02 Done survey. izin OK. 09/02 sudah anwijzing dan perizinan, plan pembuatan BOQ dan KML survey. 29/01 anwijzing OK, proses perizinan. 28/01 Plan survey HI.. 21/01 plansurvey 28 Jan | BH14: MARET | BI14: 46089 | BO14: ACH GOLIVE | BP14: =BP12/BB3 -> 17.75 | BQ14: =BQ12/BC3 -> 17.625 | BS14: PADANG | BT14: 1140 | BU14: =SUMIFS( 'PT2 UNTSEL 2026'!$AS:$AS, 'PT2 UNTSEL 2026'!$AF:$AF,"padang", 'PT2 UNTSEL 2026'!$AZ:$AZ,"GO LIVE", 'PT2 UNTSEL 2026'!$T:$T,">="&DATE(2026,3,1), 'PT2 UNTSEL 2026'!$T:$T,"<"&DATE(2026,4,1) ) -> 72 | BV14: =BU14/BT14 -> 0.063157895 | BW14: 3711 | BX14: ='REPORT GOLIVE JPP - OLO'!U13 -> 160 | BY14: =BX14/BW14 -> 0.043115063 | BZ14: =BT14+BW14 -> 4851 | CA14: =BU14+BX14 -> 232 | CB14: =CA14/BZ14 -> 0.047825191 | CD14: PADANG | CE14: 5430 | CF14: =SUMIFS( 'PT2 UNTSEL 2026'!$AS:$AS, 'PT2 UNTSEL 2026'!$AF:$AF,"padang", 'PT2 UNTSEL 2026'!$AZ:$AZ,"GO LIVE") -> 328 | CG14: =CF14/CE14 -> 0.060405157 | CH14: 11653 | CI14: =SUMIFS(K10:K3194,H10:H3194,"padang",R10:R3194,"golive") -> 0 | CJ14: =CI14/CH14 -> 0 | CK14: =CE14+CH14 -> 17083 | CL14: =CF14+CI14 -> 328 | CM14: =CL14/CK14 -> 0.019200375
